<robot name="robot">
  <link name="base_link">
    <visual>
      <origin xyz="0 0 0.5" rpy="0 0 0" />
      <geometry>
        <box size="1 1 0.5" />
      </geometry>
      <material name="base_link-material">
        <color rgba="0.783537791521566 0.09305896283800832 0.2663556047920505 1" />
      </material>
    </visual>
    <collision>
      <origin xyz="0 0 0.5" rpy="0 0 0" />
      <geometry>
        <box size="1 1 0.5" />
      </geometry>
    </collision>
    <inertial>
      <origin xyz="0 0 0.5" rpy="0 0 0" />
      <mass value="1" />
      <inertia ixx="0.16666666666666666" ixy="0" ixz="0" iyy="0.16666666666666666" iyz="0" izz="0.16666666666666666" />
    </inertial>
  </link>
  <link name="cylinder1">
    <visual>
      <origin xyz="0 0 0" rpy="0 0 0" />
      <geometry>
        <cylinder radius="0.5" length="1" />
      </geometry>
      <material name="cylinder1-material">
        <color rgba="0.008568125615105716 0.9734452903978066 0.22322795730611386 1" />
      </material>
    </visual>
    <collision>
      <origin xyz="0 0 0" rpy="0 0 0" />
      <geometry>
        <cylinder radius="0.5" length="1" />
      </geometry>
    </collision>
    <inertial>
      <origin xyz="0 0 0" rpy="0 0 0" />
      <mass value="1" />
      <inertia ixx="0.3333333333333333" ixy="0" ixz="0" iyy="0.5" iyz="0" izz="0.3333333333333333" />
    </inertial>
  </link>
  <joint name="base_link_to_cylinder1" type="revolute">
    <parent link="base_link" />
    <child link="cylinder1" />
    <origin xyz="0 0 0.9992183057181196" rpy="1.5707963267948963 0 0" />
    <axis xyz="0 0 1"/>
    <limit effort="1000.0" lower="-1" upper="1" velocity="0.5"/>  </joint>
  <link name="cube2">
    <visual>
      <origin xyz="0 0 0" rpy="0 0 0" />
      <geometry>
        <box size="0.5 0.5 2" />
      </geometry>
      <material name="cube2-material">
        <color rgba="0.21952619971859377 0.07036009568874305 0.2917706498067336 1" />
      </material>
    </visual>
    <collision>
      <origin xyz="0 0 0" rpy="0 0 0" />
      <geometry>
        <box size="0.5 0.5 2" />
      </geometry>
    </collision>
    <inertial>
      <origin xyz="0 0 0" rpy="0 0 0" />
      <mass value="1" />
      <inertia ixx="0.16666666666666666" ixy="0" ixz="0" iyy="0.16666666666666666" iyz="0" izz="0.16666666666666666" />
    </inertial>
  </link>
  <joint name="cylinder1_to_cube2" type="fixed">
    <parent link="cylinder1" />
    <child link="cube2" />
    <origin xyz="0 1.3965994545275549 2.7755575615628914e-16" rpy="-1.5707963267948963 0 0" />
  </joint>
  <link name="cylinder1-copy0">
    <visual>
      <origin xyz="0 0 0" rpy="0 0 0" />
      <geometry>
        <cylinder radius="0.5" length="1" />
      </geometry>
      <material name="cylinder1-copy0-material">
        <color rgba="0.008568125615105716 0.9734452903978066 0.22322795730611386 1" />
      </material>
    </visual>
    <collision>
      <origin xyz="0 0 0" rpy="0 0 0" />
      <geometry>
        <cylinder radius="0.5" length="1" />
      </geometry>
    </collision>
    <inertial>
      <origin xyz="0 0 0" rpy="0 0 0" />
      <mass value="1" />
      <inertia ixx="0.3333333333333333" ixy="0" ixz="0" iyy="0.5" iyz="0" izz="0.3333333333333333" />
    </inertial>
  </link>
  <joint name="cube2_to_cylinder1-copy0" type="revolute">
    <parent link="cube2" />
    <child link="cylinder1-copy0" />
    <origin xyz="0 -3.255161796279601e-17 1.3082192344265438" rpy="1.5707963267948963 0 0" />
    <axis xyz="0 0 1"/>
    <limit effort="1000.0" lower="-1" upper="1" velocity="0.5"/>  </joint>
  <link name="cube2-copy0">
    <visual>
      <origin xyz="0 0 0" rpy="0 0 0" />
      <geometry>
        <box size="0.5 0.5 2" />
      </geometry>
      <material name="cube2-copy0-material">
        <color rgba="0.21952619971859377 0.07036009568874305 0.2917706498067336 1" />
      </material>
    </visual>
    <collision>
      <origin xyz="0 0 0" rpy="0 0 0" />
      <geometry>
        <box size="0.5 0.5 2" />
      </geometry>
    </collision>
    <inertial>
      <origin xyz="0 0 0" rpy="0 0 0" />
      <mass value="1" />
      <inertia ixx="0.16666666666666666" ixy="0" ixz="0" iyy="0.16666666666666666" iyz="0" izz="0.16666666666666666" />
    </inertial>
  </link>
  <joint name="cylinder1-copy0_to_cube2-copy0" type="fixed">
    <parent link="cylinder1-copy0" />
    <child link="cube2-copy0" />
    <origin xyz="0 1.3965994545275549 2.7755575615628914e-16" rpy="-1.5707963267948963 0 0" />
  </joint>
  <link name="camera_link">
    <visual>
      <origin xyz="0 0 0" rpy="0 0 0" />
      <geometry>
        <box size="0.0254 0.1 0.0254" />
      </geometry>
      <material name="camera_link-material">
        <color rgba="0.8468732315065057 0.8468732315065057 0.8468732315065057 1" />
      </material>
    </visual>
    <collision>
      <origin xyz="0 0 0" rpy="0 0 0" />
      <geometry>
        <box size="0.0254 0.1 0.0254" />
      </geometry>
    </collision>
    <inertial>
      <origin xyz="0 0 0" rpy="0 0 0" />
      <mass value="1" />
      <inertia ixx="0.16666666666666666" ixy="0" ixz="0" iyy="0.16666666666666666" iyz="0" izz="0.16666666666666666" />
    </inertial>

    <sensor name="realsense_camera" type="camera">
        <always_on>true</always_on>
        <update_rate>30</update_rate>
        <origin>0 0 0 0 0 0</origin>
        <camera>
            <horizontal_fov>1.3962634</horizontal_fov>
            <image>
                <width>1920</width>
                <height>1080</height>
                <format>R8G8B8</format>
            </image>
            <clip>
                <near>0.105</near>
                <far>10</far>
            </clip>
            <noise>
                <type>gaussian</type>
                <mean>0.01</mean>
            </noise>
        </camera>
    </sensor>
  </link>
  <joint name="cube2-copy0_to_camera_link" type="fixed">
    <parent link="cube2-copy0" />
    <child link="camera_link" />
    <origin xyz="-0.2929320622248368 0.001887887757991127 1.04034649007794" rpy="1.8521237935984154e-16 0.6800000000000002 -1.727159822628795e-16" />
  </joint>
</robot>